<?xml version="1.0" ?>
<!-- =================================================================================== -->
<!-- |    This document was autogenerated by xacro from racecar-mit-phys.urdf.xacro    | -->
<!-- |    EDITING THIS FILE BY HAND IS NOT RECOMMENDED                                 | -->
<!-- =================================================================================== -->
<!-- Originally from https://github.com/mit-racecar/racecar_simulator/blob/master/racecar.xacro -->
<!-- A simple model of the racecar for rviz -->
<robot name="racecar">
  <material name="black">
    <color rgba="0.2 0.2 0.2 1."/>
  </material>
  <material name="blue">
    <color rgba="0.3 0.57 1. 1."/>
  </material>
  <!-- MAIN FILE -->
  <link name="base">
    <visual>
      <origin rpy="0 0 0" xyz="0 0 0"/>
      <geometry>
        <box size="0.001 0.001 0.001"/>
      </geometry>
    </visual>
    <!-- <inertial>
			<origin
				xyz="0 0 0"
				rpy="0 0 0" />
			<mass
				value="0.1" />
      <xacro:insert_block name="chassis_inertia"/>
		</inertial> -->
  </link>
  <link name="chassis">
    <visual>
      <origin xyz="0.1625 0 0.09"/>
      <geometry>
        <box size="0.325 0.2 0.1"/>
      </geometry>
      <material name="blue"/>
    </visual>
    <collision>
      <geometry>
        <box size="0.325 0.2 0.1"/>
      </geometry>
    </collision>
    <inertial>
      <mass value="1"/>
    </inertial>
  </link>
  <joint name="base_to_chassis" type="fixed">
    <origin rpy="0 0 0" xyz="0 0 0"/>
    <parent link="base"/>
    <child link="chassis"/>
  </joint>
  <joint name="chassis_to_laser_model" type="fixed">
    <parent link="chassis"/>
    <child link="laser_model"/>
    <origin xyz="0.275 0 0.165"/>
  </joint>
  <link name="laser_model">
    <visual>
      <geometry>
        <cylinder length="0.05" radius="0.026"/>
      </geometry>
      <material name="black"/>
    </visual>
    <inertial>
      <mass value="1"/>
    </inertial>
  </link>
  <joint name="chassis_to_back_left_wheel" type="continuous">
    <parent link="chassis"/>
    <child link="back_left_wheel"/>
    <origin xyz="0 0.1225 0.05"/>
    <axis xyz="0 1 0"/>
  </joint>
  <link name="back_left_wheel">
    <visual>
      <geometry>
        <cylinder length="0.045" radius="0.05"/>
      </geometry>
      <material name="black"/>
      <origin rpy="1.5707963267948966 0 0"/>
    </visual>
    <collision>
      <geometry>
        <cylinder length="0.045" radius="0.05"/>
      </geometry>
      <material name="black"/>
      <origin rpy="1.5707963267948966 0 0"/>
    </collision>
    <inertial>
      <mass value="1"/>
    </inertial>
  </link>
  <joint name="chassis_to_back_right_wheel" type="continuous">
    <parent link="chassis"/>
    <child link="back_right_wheel"/>
    <origin xyz="0 -0.1225 0.05"/>
    <axis xyz="0 1 0"/>
  </joint>
  <link name="back_right_wheel">
    <visual>
      <geometry>
        <cylinder length="0.045" radius="0.05"/>
      </geometry>
      <material name="black"/>
      <origin rpy="1.5707963267948966 0 0"/>
    </visual>
    <collision>
      <geometry>
        <cylinder length="0.045" radius="0.05"/>
      </geometry>
      <material name="black"/>
      <origin rpy="1.5707963267948966 0 0"/>
    </collision>
    <inertial>
      <mass value="1"/>
    </inertial>
  </link>
  <joint name="chassis_to_front_left_hinge" type="revolute">
    <parent link="chassis"/>
    <child link="front_left_hinge"/>
    <origin xyz="0.325 0.1225 0.05"/>
    <axis xyz="0 0 1"/>
    <!-- <limit lower="${-1 * pi / 6}" upper="${pi / 6}" effort=1000/> -->
  </joint>
  <link name="front_left_hinge">
    <inertial>
      <mass value="0.01"/>
    </inertial>
  </link>
  <joint name="front_left_hinge_to_wheel" type="revolute">
    <parent link="front_left_hinge"/>
    <child link="front_left_wheel"/>
    <axis xyz="0 1 0"/>
  </joint>
  <link name="front_left_wheel">
    <visual>
      <geometry>
        <cylinder length="0.045" radius="0.05"/>
      </geometry>
      <material name="black"/>
      <origin rpy="1.5707963267948966 0 0"/>
    </visual>
    <collision>
      <geometry>
        <cylinder length="0.045" radius="0.05"/>
      </geometry>
      <material name="black"/>
      <origin rpy="1.5707963267948966 0 0"/>
    </collision>
    <inertial>
      <mass value="1"/>
    </inertial>
  </link>
  <joint name="chassis_to_front_right_hinge" type="revolute">
    <parent link="chassis"/>
    <child link="front_right_hinge"/>
    <origin xyz="0.325 -0.1225 0.05"/>
    <axis xyz="0 0 1"/>
    <!-- <limit lower="${-1 * pi / 6}" upper="${pi / 6}" effort=1000/> -->
  </joint>
  <link name="front_right_hinge">
    <inertial>
      <mass value="0.01"/>
    </inertial>
  </link>
  <joint name="front_right_hinge_to_wheel" type="revolute">
    <parent link="front_right_hinge"/>
    <child link="front_right_wheel"/>
    <axis xyz="0 1 0"/>
  </joint>
  <link name="front_right_wheel">
    <visual>
      <geometry>
        <cylinder length="0.045" radius="0.05"/>
      </geometry>
      <material name="black"/>
      <origin rpy="1.5707963267948966 0 0"/>
    </visual>
    <collision>
      <geometry>
        <cylinder length="0.045" radius="0.05"/>
      </geometry>
      <material name="black"/>
      <origin rpy="1.5707963267948966 0 0"/>
    </collision>
    <inertial>
      <mass value="1"/>
    </inertial>
  </link>
</robot>

